Workbook
Name Slicer_Price_Category1: #N/A

Sheet Dashboard
A1: SEPHORA BEAUTY PRODUCTS DASHBOARD
A4: Total Products | H4: Average Rating | U4: Average Price
B5: =Data_quality!B2 -> 500 | J5: =Data_quality!B11 -> 4.1957166 | U5: =Data_quality!B8 -> 53.0727

Sheet excel project
A1: product_id | B1: product_name | C1: brand_id | D1: brand_name | E1: loves_count | F1: rating | G1: reviews | H1: size | I1: variation_type | J1: variation_value | K1: variation_desc | L1: ingredients | M1: price_usd | N1: value_price_usd | O1: sale_price_usd | P1: limited_edition | Q1: new | R1: online_only | S1: out_of_stock | T1: sephora_exclusive | U1: highlights | V1: primary_category | W1: secondary_category | X1: tertiary_category | Y1: child_count | Z1: child_max_price | AA1: child_min_price | AC1: Random_number
A2: P453279 | B2: Mini Intenso Smoothing Mask for Thick Hair | C2: 6159 | D2: Rossano Ferretti Parma | E2: 557 | F2: 3 | G2: 2 | H2: 1.7 oz/ 50 mL | I2: Size | J2: 1.7 oz/ 50 mL | M2: 18 | P2: 0 | Q2: 0 | R2: 1 | S2: 0 | T2: 0 | U2: ['Vegan', 'Hydrating', 'Clean at Sephora', 'Good for: Frizz', 'Good for: Dryness', 'Cruelty-Free'] | V2: Hair | W2: Hair Styling & Treatments | X2: Hair Masks | Y2: 0 | AC2: 0.00028886723
A3: P501449 | B3: PEPTIDE PREP Clarifying Detox Shampoo | C3: 6472 | D3: K18 Biomimetic Hairscience | E3: 24418 | F3: 4.7944 | G3: 603 | H3: 8.5 oz / 250 mL | I3: Size | J3: 8.5 oz / 250 mL | L3: ['Water (Aqua) (Eau), Sodium C14-16 Olefin Sulfonate, Cocamidopropyl Hydroxysultaine, Salicylic Acid, Charcoal Powder, sh-Oligopeptide-78, Panthenol,', 'Glycerin, Sodium Phytate, Guar Hydroxypropyltrimonium Chloride, Caprylyl Glycol, Caprylhydroxamic Acid, Citric Acid, Potassium Hydroxide, Sodium Hydroxide, Fragrance (Parfum), Benzyl Salicylate, Limonene.'] | M3: 38 | P3: 0 | Q3: 0 | R3: 0 | S3: 0 | T3: 1 | U3: ['Vegan', 'Good for: Color Care', 'Clean at Sephora', 'All Hair Types', 'Salicylic Acid', 'Good for: Oily Scalp'] | V3: Hair | W3: Shampoo & Conditioner | X3: Shampoo | Y3: 1 | Z3: 14 | AA3: 14 | AC3: 0.00034055583
A4: P501526 | B4: Even Better All-Over Primer + Color Corrector | C4: 1254 | D4: CLINIQUE | E4: 2159 | F4: 3.8 | G4: 5 | H4: 0.2 oz / 6 mL | I4: Color | J4: Peach | K4: very fair to moderately fair complexions | L4: ['Water/Aqua/Eau, Methyl Trimethicone, Trimethylsiloxysilicate, Dimethicone, Butylene Glycol, Phenyl Trimethicone, Neopentyl Glycol Diheptanoate, Niacinamide, Hydroxyethyl Urea, Lauryl PEG-9 Polydimethylsiloxyethyl Dimethicone, Glycerin, Sodium Polyaspartate, Ascorbyl Glucoside, Phytosphingosine, Palmitoyl Hexapeptide-12, Sodium Hyaluronate, Resveratrol, Acetyl Hexapeptide-8, Caffeine, Magnesium Ascorbyl Phosphate, Tetrahexyldecyl Ascorbate, Polygonum Cuspidatum Root Extract, Tocopheryl Acetate, PEG-10 Dimethicone, Triethyl Citrate, Sigesbeckia Orientalis (St. Paul Wort) Extract, Micrococcus Lysate, Isopropyl Isostearate, PPG-15 Stearyl Ether, Salicylic Acid, Trihydroxystearin, Caprylyl Glycol, Sorbitol, Trehalose, Silica, Dimethicone/PEG-10/15 Crosspolymer, Xanthan Gum, Magnesium Aluminum Silicate, Lecithin, Triethoxycaprylylsilane, Zinc Stearate, Laureth-7, PEG-8, Ammonium Acryloyldimethyltaurate/VP Copolymer, Glyceryl Polymethacrylate, Alumina, Propylene Glycol Caprylate, Polysilicone-11, Disteardimonium Hectorite, Citric Acid, Hexylene Glycol, Dipropylene Glycol, Vinyl Dimethicone/Methicone Silsesquioxane Crosspolymer, Sodium Chloride, Sodium Hydroxide, BHT, Disodium EDTA, Sodium Citrate, Potassium Sorbate, Phenoxyethanol, [+/- Mica, Titanium Dioxide (CI 77891), Iron Oxides (CI 77491), Iron Oxides (CI 77492), Iron Oxides (CI 77499), Bismuth Oxychloride (CI 77163), Ultramarines (CI 77007), Chromium Oxide Greens (CI 77288)].'] | M4: 29 | P4: 0 | Q4: 0 | R4: 1 | S4: 0 | T4: 0 | U4: ['Natural Finish', 'Hyaluronic Acid', 'Vitamin C', 'Good for: Dark Circles', 'Long-wearing', 'Niacinamide'] | V4: Makeup | W4: Face | X4: Face Primer | Y4: 1 | Z4: 29 | AA4: 29 | AC4: 0.00057713968
A5: P422093 | B5: Bloom Eau de Parfum For Her | C5: 1063 | D5: Gucci | E5: 69220 | F5: 4.1913 | G5: 1317 | H5: 1.6 oz/ 50 mL | I5: Size + Concentration + Formulation | J5: 1.6 oz/ 50 mL Eau de Parfum Spray | L5: ['Alcohol Denat., Fragrance, Water, Ethylhexyl Methoxycinnamate, Diethylamino Hydroxybenzoyl Hexyl Benzoate, Bht, Linalool, Benzyl Alcohol, Cinnamal, Hydroxycitronellal, Citronellol, Geraniol, Eugenol, Isoeugenol, Farnesol, Benzyl Benzoate, Hexyl Cinnamal, Citral.'] | M5: 123 | P5: 0 | Q5: 0 | R5: 0 | S5: 0 | T5: 0 | U5: ['Floral Scent', 'Layerable Scent'] | V5: Fragrance | W5: Women | X5: Perfume | Y5: 3 | Z5: 155 | AA5: 38 | AC5: 0.00088413043
A6: P9549 | B6: ALLURE Eau de Parfum | C6: 1065 | D6: CHANEL | E6: 7564 | F6: 4.3077 | G6: 26 | H6: 1.7 oz | I6: Size | J6: 1.7 oz | L6: ['Alcohol, Fragrance, Water, Linalool, Benzyl Salicylate, Limonene, Hexyl Cinnamal, Hydroxycitronellal, Citronellol, Geraniol, Alpha-Isomethyl Ionone, Coumarin, Citral, Benzyl Benzoate, Farnesol, Benzyl Alcohol, Amyl Cinnamal, Isoeugenol, Eugenol, Ethylhexyl Methoxycinnamate, Butyl Methoxydibenzoylmethane, Ethylhexyl Salicylate, Ci 14700 (Red 4), Ci 42090 (Blue 1), Ci 15985 (Yellow 6), Ci 19140 (Yellow 5), Il18-1.'] | M6: 122 | P6: 0 | Q6: 0 | R6: 0 | S6: 0 | T6: 0 | V6: Fragrance | W6: Women | X6: Perfume | Y6: 0 | AC6: 0.0010133058
A7: P408230 | B7: V-Facial Instant Depuffing Face Mask | C7: 2082 | D7: Clarins | E7: 26393 | F7: 4.7547 | G7: 159 | H7: 2.5 oz/ 74 mL | I7: Size | J7: 2.5 oz/ 74 mL | L7: ['Water, Glycerin, Kaolin, Alcohol, Cetearyl Ethylhexanoate, Cetearyl Alcohol, Betaine, Cetyl Alcohol, Polymethyl Methacrylate, Butylene Glycol, Caffeine, Glyceryl Stearate, Ci 77891/Titanium Dioxide, Gellan Gum, Dimethicone, Phenoxyisopropanol, Escin, Ethylhexylglycerin, Sodium Cetearyl Sulfate, Sodium Lauryl Sulfate, Sodium Acrylates Copolymer, Hydrogenated Polyisobutene, Disodium Edta, Zingiber Zerumbet Extract, Parfum/Fragrance, Phospholipids, Polyglyceryl-10 Stearate, Helianthus Annuus (Sunflower) Seed Oil, Tromethamine, Alumina, Ethylene Brassylate, Xylitol, Alchemilla Vulgaris Extract, Callicarpa Japonica Fruit Extract.'] | M7: 67 | P7: 0 | Q7: 0 | R7: 0 | S7: 0 | T7: 0 | U7: ['Good for: Dullness/Uneven Texture', 'Good for: Loss of firmness', 'Without Phthalates', 'Without Parabens', 'Best for Dry, Combo, Normal Skin'] | V7: Skincare | W7: Masks | X7: Face Masks | Y7: 0 | AC7: 0.001130951
A8: P500716 | B8: 10 Day Results Kit | C8: 6018 | D8: Algenist | E8: 3206 | F8: 4.8023 | G8: 258 | L8: ['GENIUS Liquid Collagen:', 'Collagen (Vegan), Water (Aqua, Eau), Propanediol, Isononyl Isononanoate, Butylene Glycol, Glycerin, Betaine, Pentylene Glycol, Dextrin Palmitate, Collagen Amino Acids (Vegan), Parachlorella Beijerinckii Exopolysaccharides, Chlorella Protothecoides Oil, Helichrysum Stoechas Flower Extract, Cylindrotheca Fusiformis Extract, Niacinamide, Tocopherol, Palmitoyl Tripeptide-1, Palmitoyl Tetrapeptide-7, Adenosine, Helianthus Annuus (Sunflower) Seed Oil, Leuconostoc/Radish Root Ferment Filtrate, Caprylic/Capric Triglyceride, Palmitic Acid, Disodium EDTA, Carbomer, Sodium Lactate, Amodimethicone, Homosalate, Polysorbate 20, Butyl Methoxydibenzoylmethane, 1,2-Hexanediol, Caprylyl Glycol, Octocrylene, Sodium Hydroxide, Phenoxyethanol, Fragrance (Parfum), Limonene, Beta-Carotene (CI 40800).', 'Triple Algae Eye Renewal Balm with Multi-Peptide Complex:', 'Aqua (Water/Eau), Stearic Acid, Isopropyl Isostearate, Dimethicone, Glycerin, Pentylene', 'Glycol, Glyceryl Stearate SE, Cetearyl Alcohol, Butyrospermum Parkii (Shea) Butter, C12-15 Alkyl Benzoate, Limnanthes Alba (Meadowfoam) Seed Oil, Parachlorella Beijerinckii Exopolysaccharides, Corallina Officinalis Extract, Dunaliella Salina Extract, Undaria Pinnatifida Extract, Dipeptide-2, Palmitoyl Tetrapeptide-7, Palmitoyl Hexapeptide-12, Palmitoyl Tripeptide-5, Sodium Hyaluronate, Caffeine, Coffea Arabica (Coffee) Seed Oil, Tribehenin, Ceramide NG, PEG-10 Phytosterol, Tetrahexyldecyl Ascorbate, Aloe Barbadensis Leaf Juice, Tocopheryl Acetate, Bambusa Vulgaris Leaf/Stem Extract, Pisum Sativum (Pea)', 'Extract, Glucosamine HCl, Leuconostoc/Radish Root Ferment Filtrate, Camellia Sinensis Leaf Extract, Cucumis Sativus (Cucumber) Fruit Extract, Dimethicone Crosspolymer, Panthenol, Pantolactone, Caprylyl/Capryl Glucoside, Pfaffia Paniculata Root Extract, Ptychopetalum Olacoides Bark/Stem Extract, Lilium Candidum Flower Extract, Rubus Idaeus (Raspberry) Leaf Extract, Aloe Barbadensis Leaf Juice Powder, Vinyl Dimethicone/Methicone Silsesquioxane Crosspolymer, Phospholipids, Ceteareth-20, Acrylates/C10-30 Alkyl Acrylate Crosspolymer, Disodium EDTA, Aminomethyl Propanol, Caprylyl Glycol, Lactic Acid, Ethylhexylglycerin, Hexylene Glycol, Hesperidin Methyl Chalcone, Steareth-20, Citric Acid, Sodium Citrate, Chlorhexidine Digluconate, Phenoxyethanol, Potassium Sorbate, Benzyl Alcohol, Sodium Benzoate.', 'GENIUS Ultimate Anti-Aging Cream:', 'Water (Aqua, Eau), Caprylic/Capric Triglyceride, Hydrogenated Polyisobutene, Glycerin, Chlorella Protothecoides Oil, Dimethicone, Butylene Glycol, Glyceryl Stearate, PEG-100 Stearate, Butyrospermum Parkii (Shea) Butter, Pentylene Glycol, Potassium Cetyl Phosphate, Parachlorella Beijerinckii Exopolysaccharides, Collagen (Vegan), Ceramide NP, Cynara Scolymus (Artichoke) Leaf Extract, Retinyl Palmitate, Astragalus Membranaceus Root Extract, Atractylodes Macrocephala Root Extract, Iris Florentina Root Extract, Bupleurum Falcatum Root Extract, Copper Lysinate/Prolinate, Methylglucoside Phosphate, Stearalkonium Bentonite, Acrylates/C10-30 Alkyl Acrylate Crosspolymer, Silica, Caprylyl Glycol, Sodium Hydroxide, Disodium EDTA, Ethylhexylglycerin, Cetyl Alcohol, Propylene Carbonate, Quartz, Phenoxyethanol, Leuconostoc/Radish Root Ferment Filtrate, Chlorphenesin, Fragrance (Parfum), Coumarin.'] | M8: 88 | N8: 142 | P8: 0 | Q8: 0 | R8: 0 | S8: 0 | T8: 1 | U8: ['Vegan', 'Good for: Loss of firmness', 'Good for: Dark Circles', 'Collagen', 'Hydrating', 'Good for: Anti-Aging'] | V8: Skincare | W8: Value & Gift Sets | Y8: 0 | AC8: 0.0012250293
A9: P502274 | B9: Paper- Personal | C9: 7095 | D9: Commodity | E9: 664 | F9: 3.5455 | G9: 11 | H9: 3.4 oz / 100 mL | I9: Size + Concentration + Formulation | J9: 3.4 oz / 100 mL perfume spray | L9: ['SD Alcohol 40-B (Alcohol Denat.), Parfum/Fragrance, Aqua/Water/Eau.'] | M9: 135 | P9: 0 | Q9: 0 | R9: 0 | S9: 0 | T9: 1 | U9: ['Vegan', 'Unisex/ Genderless Scent', 'Clean at Sephora', 'Cruelty-Free'] | V9: Fragrance | W9: Women | X9: Perfume | Y9: 1 | Z9: 25 | AA9: 25 | AC9: 0.0012972529
A10: P462706 | B10: Epic Curl Vegan Lash Primer | C10: 5905 | D10: KVD Beauty | E10: 2352 | F10: 2.9355 | G10: 31 | L10: ['Aqua/Water/Eau, Hydrogenated Olive Oil Stearyl Esters, Bambusa Arundinacea Stem Extract, Cera, Carnauba/Copernicia, Cerifera (Carnauba) Wax/Cire De Carnauba, Oryza Sativa Cera/Oryza Sativa (Rice) Bran Wax, Glyceryl Stearate, Helianthus Annuus Seed Cera/Helianthus Annuus (Sunflower) Seed Wax, Bis-Diglyceryl Polyacyladipate-2, Acacia Senegal Gum, Stearic Acid, Propanediol, Palmitic Acid, Aminomethyl Propanol, Hydrolyzed Jojoba Esters, Phenoxyethanol, Sodium Dehydroacetate, Galactoarabinan, Jojoba Esters, Xanthan Gum, Ethylhexylglycerin, Talc, Kaolin, Tocopherol, Ultramarines (Ci 77007), Iron Oxides (Ci 77499), Ferric Ammonium Ferrocianide (Ci 77510).'] | M10: 24 | P10: 0 | Q10: 0 | R10: 0 | S10: 0 | T10: 0 | U10: ['Vegan', 'Liquid Formula', 'Curling'] | V10: Makeup | W10: Eye | X10: Mascara | Y10: 0 | AC10: 0.0013004317
A11: P376726 | B11: Maracuja Oil | C11: 5648 | D11: tarte | E11: 79986 | F11: 4.396 | G11: 2419 | H11: 1.7 oz/ 50 mL | I11: Size | J11: 1.7 oz/ 50 mL | L11: ['Passiflora Edulis Seed Oil, Citrus Paradisi (Grapefruit) Peel Oil, Limonene, Tocopherol, Oryza Sativa (Rice) Bran Extract, Helianthus Annuus (Sunflower) Extract, Rosmarinus Officinalis (Rosemary) Leaf Extract, Citral, Linalool.'] | M11: 48 | P11: 0 | Q11: 0 | R11: 0 | S11: 0 | T11: 0 | V11: Skincare | W11: Moisturizers | X11: Face Oils | Y11: 1 | Z11: 16 | AA11: 16 | AC11: 0.0014339801
A12: P504146 | B12: Sunday Scalp Reset Foam Pre Shampoo | C12: 5995 | D12: Bumble and bumble | E12: 292 | F12: 4.766 | G12: 47 | H12: 3.5 oz / 150 mL | I12: Size | J12: 3.5 oz / 150 mL | L12: ['Butane, Water/Aqua/Eau, Alcohol Denat., Isobutane, Glycerin, Butylene Glycol, Dimethicone, Fragrance (Parfum), Caprylic/Capric Triglyceride, PPG-8-Ceteth-20, Salicylic Acid, Caffeine, Epilobium Angustifolium Flower/Leaf/Stem Extract, Sodium Lauroamphoacetate, Panthenol, Tocopheryl Acetate, Punica Granatum (Pomegranate) Extract, Honey Extract/Mel/Extrait De Miel, Leuconostoc/Radish Root Ferment Filtrate, Wheat Amino Acids, Aloe Barbadensis Leaf Juice, Gellidiella Acerosa Extract, Hypnea Musciformis (Algae) Extract, Sargassum Filipendula (Algae) Extract, Citrus Tangerina (Tangerine), Zingiber Officinale (Ginger) Root Extract, Rice Amino Acids, Glyceryl Polyacrylate, Hydroxyethylcellulose, Biotin, Cellulose, Cocamide Mipa, Sodium Lauroyl Methyl Isethionate, Citric Acid, Linalool, Benzyl Salicylate, Citronellol, Limonene, Alpha-Isomethyl Ionone, Phenoxyethanol, Sodium Benzoate.'] | M12: 34 | P12: 0 | Q12: 0 | R12: 0 | S12: 0 | T12: 1 | U12: ['Good for: Color Care', 'Salicylic Acid', 'Without Sulfates SLS & SLES', 'Good for: Oily Scalp', 'Cruelty-Free'] | V12: Hair | W12: Hair Styling & Treatments | X12: Scalp Treatments | Y12: 0 | AC12: 0.0015458561
A13: P462356 | B13: Mini Honey Infused Hair Perfume | C13: 6328 | D13: Gisou | E13: 70086 | F13: 4.0824 | G13: 425 | H13: 1.7 oz/ 50 mL | I13: Size | J13: 1.7 oz/ 50 mL | L13: ['Alcohol Denat., Parfum (Fragrance), Aqua (Water, Eau), Mel (Honey, Miel)*, Argania Spinosa Kernel Oil, Sodium Benzotriazolyl Butylphenol Sulfonate, Tris(Tetramethylhydroxypiperidinol) Citrate, Citral**, Coumarin**, Linalool**, Hexyl Cinnamal**, Limonene**, CI 19140 (Yellow 5), CI 14700 (Red 4).'] | M13: 44 | P13: 0 | Q13: 0 | R13: 0 | S13: 0 | T13: 0 | U13: ['Layerable Scent', 'Fresh Scent', 'Clean at Sephora', 'All Hair Types', 'Good for: Frizz'] | V13: Hair | W13: Hair Styling & Treatments | X13: Hair Styling Products | Y13: 0 | AC13: 0.0016757512
A14: P462386 | B14: Drying Cream | C14: 8017 | D14: Mario Badescu | E14: 1635 | F14: 3.75 | G14: 4 | H14: 0.5 oz/ 14 g | I14: Size | J14: 0.5 oz/ 14 g | L14: ['Aqua (Water, Eau), Zinc Oxide, Cetyl Alcohol, Aloe Barbadensis Leaf Juice, Cera Alba (Beeswax, Cire dÂ´abeille), Polysorbate 80, Glycerin, Ethylhexyl Palmitate, Propylene Glycol, Sulfur, Oleth-10, Paraffinum Liquidum (Mineral Oil, Huile MinÃ©rale), Ichthammol, Hydrolyzed Yeast Protein, Triticum Vulgare (Wheat) Starch, Arctium Lappa Root Extract, Cysteine, Niacinamide, Panthenol, Nasturtium Officinale Flower/Leaf Extract, Citrus Limon (Lemon) Fruit Extract, Allantoin, Biotin, Arginine, Leucine, Lysine, Tyrosine, Valine, Glutamic Acid, Cellulose Gum, Polysorbate 20, Maltodextrin, Zinc Chloride, Glyceryl Acrylate/Acrylic Acid Copolymer, Pyridoxine HCl, Parfum (Fragrance), Sodium Chloride, Methylparaben, Propylparaben, Potassium Sorbate, Citric Acid, Sodium Benzoate, Chlorphenesin, Disodium EDTA, Phenoxyethanol, Benzyl Benzoate, Alpha-Isomethyl Ionone, Limonene, Linalool, CI 77891 (Titanium Dioxide).'] | M14: 17 | P14: 0 | Q14: 0 | R14: 1 | S14: 0 | T14: 0 | V14: Skincare | W14: Treatments | X14: Blemish & Acne Treatments | Y14: 0 | AC14: 0.0017300769
A15: P437657 | B15: Scalp Care Dry Scalp Treatment | C15: 5936 | D15: Living Proof | E15: 33713 | F15: 4.301 | G15: 309 | H15: 3.4 oz/ 100 mL | I15: Size | J15: 3.4 oz/ 100 mL | L15: ['Water/Eau/Aqua, Glycerin, Niacinamide, Sodium Hyaluronate, Trehalose, Urea, Serine, Algin, Pentylene Glycol, Pullulan, Lecithin, Glyceryl Polyacrylate, C13-15 Alkane, Caprylyl Glycol, Disodium Phosphate, Potassium Phosphate, Hydroxyethyl Acrylate/Sodium Acryloyldimethyl Taurate Copolymer, Hydroxyacetophenone, Caesalpinia Spinosa Gum, Sclerotium Gum, Xanthan Gum, Isohexadecane, Ethylhexylglycerin, Polysorbate 60, Fragrance/Parfum.'] | M15: 37 | P15: 0 | Q15: 0 | R15: 0 | S15: 0 | T15: 0 | U15: ['Vegan', 'All Hair Types', 'Without Parabens', 'Without Silicones', 'Without Sulfates SLS & SLES', 'Good for: Flaky/Dry Scalp'] | V15: Hair | W15: Hair Styling & Treatments | X15: Scalp Treatments | Y15: 0 | AC15: 0.001922603
A16: P457245 | B16: Rose Perfecto Tinted Liquid Balm | C16: 1133 | D16: Givenchy | E16: 62416 | F16: 4.3079 | G16: 367 | H16: .2 oz/ 6mL | I16: Color | J16: 001 Pink Irresistible | K16: transparent pink, custom to your PH | L16: ['C10-30 Cholesterol/Lanosterol Esters, Isononyl Isononanoate, Polyglyceryl-2 Triisostearate, Hydrogenated Polyisobutene, Pentaerythrityl Tetraisostearate, Copernicia Cerifera (Carnauba) Wax, Ethylene/Propylene/Styrene Copolymer, Glyceryl Behenate/Eicosadioate, Ethylhexyl Palmitate, Butyrospermum Parkii (Shea) Butter, Butyrospermum Parkii (Shea) Butter Unsaponifiables, Menthoxypropanediol, Parfum (Fragrance), Butylene/Ethylene/Styrene Copolymer, Diisostearyl Malate, Ascorbyl Tetraisopalmitate, Trimethylolpropane Triisostearate, Pentaerythrityl Tetra-Di-T-Butyl Hydroxyhydrocinnamate, Trihydroxystearin, Schinus Terebinthifolius Seed Extract, Tocopherol, Sodium Hyaluronate, Propyl Gallate, [+/- Ci 77499 (Iron Oxides), Ci 77891 (Titanium Dioxide), Ci 45410 (Red 27), Ci 15850 (Red 6 - Red 7)].'] | M16: 38 | P16: 0 | Q16: 0 | R16: 0 | S16: 0 | T16: 0 | U16: ['Radiant Finish', 'Hyaluronic Acid', 'Liquid Formula', 'Plumping', 'Vitamin C', 'Hydrating'] | V16: Makeup | W16: Lip | X16: Lip Balm & Treatment | Y16: 5 | Z16: 38 | AA16: 38 | AC16: 0.0021800229
A17: P505364 | B17: Afterglow Sensual Shine Hydrating Lipstick | C17: 3976 | D17: NARS | E17: 688 | H17: .05 oz / 1.5 g | I17: Color | J17: ORGASM | L17: ['Tridecyl Trimellitate, Hydrogenated Polyisobutene, Phenylpropyldimethylsiloxysilicate, Synthetic Wax, Mica, Ricinus Communis (Castor) Seed Oil, Hydrogenated Vegetable Oil, Polyethylene, Diisostearyl Malate, Diglyceryl Sebacate/Isopalmitate, Dimethicone, Dicalcium Phosphate, Phytosteryl/Isostearyl/Cetyl/Stearyl/Behenyl Dimer Dilinoleate, Gardenia Taitensis Flower Extract, Moringa Oleifera Seed Extract, Polyhydroxystearic Acid, Isopropyl Myristate, Isostearic Acid, Ethylhexyl Palmitate, Lecithin, Polyglyceryl-3 Polyricinoleate, Triethoxycaprylylsilane, Polysilicone-11, Butyrospermum Parkii (Shea) Butter, Ethylene/Propylene Copolymer, Pentaerythrityl Tetra-Di-T-Butyl Hydroxyhydrocinnamate, Tocopherol, Water/Aqua/Eau, Collagen, Leuconostoc/Radish Root Ferment Filtrate, Hydrogenated Coco-Glycerides, Sodium Hyaluronate, Hydrogenated Castor Oil, Tocopheryl Acetate, Cocos Nucifera (Coconut) Oil, Simmondsia Chinensis (Jojoba) Seed Oil, Mangifera Indica (Mango) Seed Butter, Olea Europaea (Olive) Fruit Oil, Caprylyl Glycol, Glyceryl Caprylate, Glycerin, [+/-(May Contain/Peut Contenir): Iron Oxides (Ci 77491, Ci 77492, Ci 77499), Red 7 Lake (Ci 15850), Titanium Dioxide (Ci 77891), Yellow 5 Lake (Ci 19140)].'] | M17: 32 | P17: 0 | Q17: 1 | R17: 0 | S17: 1 | T17: 0 | U17: ['Stick Formula', 'High Shine Finish', 'Hydrating', 'Oil Free', 'Without Parabens'] | V17: Makeup | W17: Lip | X17: Lipstick | Y17: 9 | Z17: 32 | AA17: 32 | AC17: 0.0022873437
A18: P417107 | B18: The Moisturizing Soft Lotion | C18: 6201 | D18: La Mer | E18: 4580 | F18: 4.0704 | G18: 71 | H18: 1.7 oz/ 50 mL | I18: Size | J18: 1.7 oz/ 50 mL | L18: ['Algae (Seaweed) Extract, Petrolatum, Isocetyl Stearoyl Stearate, Butyrospermum Parkii (Shea Butter), Butylene Glycol, Cyclopentasiloxane, Dimethicone, Glyceryl Stearate, Cetyl Esters, Phenyl Trimethicone, Diethylhexyl Succinate, Cyclohexasiloxane, Cholesterol, Steareth-10, Glyceryl Stearate Se, Polysilicone-11, Sesamum Indicum (Sesame) Seed Oil, Medicago Sativa (Alfalfa) Seed Powder, Helianthus Annuus (Sunflower) Seedcake, Prunus Amygdalus Dulcis (Sweet Almond) Seed Meal, Eucalyptus Globulus (Eucalyptus) Leaf Oil, Sodium Gluconate, Copper Gluconate, Calcium Gluconate, Magnesium Gluconate, Zinc Gluconate, Tocopheryl Succinate, Niacin, Sesamum Indicum (Sesame) Seed Powder, Water\\Aqua\\Eau, Salicornia Herbacea Extract, Sigesbeckia Orientalis (St. Paul Wort) Extract, Citrus Aurantifolia (Lime) Peel Extract, Sea Salt\\Maris Sal\\Sel Marin, Chlorella Vulgaris Extract, Hydrolyzed Rice Extract, Micrococcus Lysate, Laminaria Digitata Extract, Plankton Extract, Caffeine, Glucose Oxidase, Trehalose, Sucrose, Acetyl Hexapeptide-8, Lactoperoxidase, Hydrolyzed Algin, Glyceryl Dilaurate, Alcaligenes Polysaccharides, Isohexadecane, Caprylic/Capric Triglyceride, Dipalmitoyl Hydroxyproline, Distearyldimonium Chloride, Glycerin, Tocopheryl Acetate, Steareth-21, Polyquaternium-51, Saccharide Isomerate, Tetrahexyldecyl Ascorbate, Sodium Pca, Urea, Glucose, Polysorbate 80, Sodium Hyaluronate, Cetyl Alcohol, Alcohol Denat., Acrylamide/Sodium Acryloyldimethyltaurate Copolymer, Fragrance (Parfum), Lecithin, BHT, Linalool, Citronellol, Hydroxycitronellal, Geraniol, Limonene, Benzyl Salicylate, Phenoxyethanol.'] | M18: 320 | P18: 0 | Q18: 0 | R18: 0 | S18: 0 | T18: 0 | U18: ['Best for Combination Skin', 'Good for: Pores', 'Without Sulfates SLS & SLES', 'Without Parabens', 'Without Phthalates'] | V18: Skincare | W18: Moisturizers | X18: Moisturizers | Y18: 0 | AC18: 0.0023807333
A19: P467973 | B19: Intensive Eye Renewal Cream with Firming Peptides | C19: 6314 | D19: Shani Darden Skin Care | E19: 12224 | F19: 4.2087 | G19: 254 | H19: 0.5 oz/ 15 mL | I19: Size | J19: 0.5 oz/ 15 mL | L19: ['Water (Aqua), Caprylic/Capric Triglyceride, Diheptyl Succinate, Capryloyl Glycerin/Sebacic Acid Copolymer, Butyrospermum Parkii (Shea Butter), Albizia Julibrissin Bark Extract, Darutoside, Cetearyl Alcohol, Pentylene Glycol, Glycerin, Niacinamide, Castanea Sativa (Chestnut) Seed Extract, Sorbitan Stearate, Glyceryl Stearate, PEG-100 Stearate, Hydroxyethyl Acrylate/Sodium Acryloyldimethyl Taurate Copolymer, Hydrolyzed Pea Protein, Lecithin, Olea Europaea (Olive) Fruit Oil, Phytosterols, Squalane, Ceramide NP, Propanediol, Physalis Angulata Extract, Tocopheryl (Vitamin E) Acetate, Cucumis Sativus (Cucumber) Fruit Extract, Tetrasodium Glutamate Diacetate, Phenoxyethanol, Ethylhexylglycerin, Chlorphenesin.'] | M19: 68 | P19: 0 | Q19: 0 | R19: 0 | S19: 0 | T19: 1 | V19: Skincare | W19: Eye Care | X19: Eye Creams & Treatments | Y19: 0 | AC19: 0.002448324
A20: P454967 | B20: Amalfi Lemon & Mint Reed Diffuser | C20: 7025 | D20: NEST New York | E20: 1829 | F20: 4.4444 | G20: 9 | H20: 5.9 oz/ 175 mL | I20: Size + Concentration + Formulation | J20: 5.9 oz/ 175 mL diffuser | M20: 58 | P20: 0 | Q20: 0 | R20: 0 | S20: 0 | T20: 0 | V20: Fragrance | W20: Candles & Home Scents | X20: Diffusers | Y20: 0 | AC20: 0.0025401527
A21: P504363 | B21: Lip Snatcher Hydrating Liquid Lipstick and Lip Gloss Duo | C21: 6326 | D21: ONE/SIZE by Patrick Starrr | E21: 18228 | F21: 4.297 | G21: 165 | H21: .24 oz / 7 mL | I21: Color | J21: Joelapuss | K21: pearlescent & matte medium pink | L21: ['CrÃ©me:', 'Isododecane, Octyldodecanol, Dicalcium Phosphate, Silica, Hydrogenated Styrene/Isoprene Copolymer, Synthetic Fluorphlogopite, Trimethylsiloxysilicate, Disteardimonium Hectorite, Ethyl Vanillin, Tocopheryl Acetate, Gossypium Herbaceum (Cotton) Seed Oil, Helianthus Annuus (Sunflower) Seed Oil, Pentaerythrityl Tetra-Di-T-Butyl Hydroxyhydrocinnamate, Ricinus Communis (Castor) Seed Oil, Hydrolyzed Sodium Hyaluronate, Sodium Hyaluronate, Hydrogenated Castor Oil, Lupinus Albus Seed Extract, Tocopherol. May Contain/Peut Contenir (Â±): Red 7 Lake (CI 15850), Titanium Dioxide (CI 77891), Red 28 Lake (CI 45410), Yellow 6 Lake (CI 15985), Iron Oxides (CI 77491, CI 77492), Blue 1 Lake (CI 42090).', 'Gloss:', 'Polybutene, Octyldodecanol, Hydrogenated Polyisobutene, Silica Dimethyl Silylate, Calcium Sodium Borosilicate, VP/Hexadecene Copolymer, Hydrogenated Styrene/Isoprene Copolymer, Caprylic/Capric Triglyceride, Ethyl Vanillin, Tocopheryl Acetate, Synthetic Fluorphlogopite, Pentaerythrityl Tetra-Di-T-Butyl Hydroxyhydrocinnamate, Dicalcium Phosphate, Tin Oxide, Helianthus Annuus (Sunflower) Seed Oil, Ricinus Communis (Castor) Seed Oil, Hydrolyzed Sodium Hyaluronate, Sodium Hyaluronate, Hydrogenated Castor Oil, Lupinus Albus Seed Extract, Jasminum Officinale (Jasmine) Flower Extract, Tocopherol. May Contain/Peut Contenir (Â±): Titanium Dioxide (CI 77891), Iron Oxides (CI 77491, CI 77492), Red 7 Lake (CI 15850), Yellow 5 (CI 19140), Blue 1 Lake (CI 42090).'] | M21: 28 | P21: 0 | Q21: 1 | R21: 0 | S21: 0 | T21: 1 | U21: ['Vegan', 'Liquid Formula', 'Hydrating', 'Long-wearing', 'Cruelty-Free'] | V21: Makeup | W21: Lip | X21: Lipstick | Y21: 7 | Z21: 28 | AA21: 28 | AC21: 0.0025421695
A22: P484044 | B22: The Body Duo Mini Body Scrub + Moisturizer Essentials | C22: 6352 | D22: Fenty Skin | E22: 10700 | F22: 4.2 | G22: 5 | L22: ['Buff Ryder Mini Exfoliating Body Scrub:', 'Sucrose, Glycine Soja (Soybean) Oil, Helianthus Annuus Hybrid Oil (Helianthus Annuus (Sunflower) Seed Oil), Sea Salt/Maris Sal/Sel Marin, Cocos Nucifera (Coconut) Oil, Butyrospermum Parkii (Shea) Butter, Polyglyceryl-3 Caprate, Silica, Helianthus Annuus (Sunflower) Seed Oil, Caprylic/Capric Triglyceride, Trihydroxystearin, Styrene/Butadiene Copolymer, Persea Gratissima (Avocado) Fruit Powder, Lactobacillus/Punica Granatum Fruit Ferment Extract, Papain, Bromelain, Quartz, Tocopherol, Citric Acid, Pumice, Caprylyl Glycol, Maltodextrin, Phenoxyethanol, Pentaerythrityl Tetra-Di-T-Butyl Hydroxyhydrocinnamate, Parfum/Fragrance, Hydroxycitronellal, Limonene.', 'Butta Drop Mini Whipped Oil Body Cream:', 'Aqua/Water/Eau, Cocos Nucifera (Coconut) Oil, Glycerin, Caprylic/Capric Triglyceride, Oryza Sativa (Rice) Bran Oil, Propanediol, Cetearyl Alcohol, Cetyl Ethylhexanoate, Dimethicone, Butyrospermum Parkii (Shea) Butter, Mangifera Indica (Mango) Seed Butter, Cetearyl Olivate, Diisostearyl Malate, Polyglyceryl-3 Methylglucose Distearate, Citrullus Lanatus (Watermelon) Seed Oil, Hibiscus Sabdariffa Seed Oil, Adansonia Digitata Seed Oil, Malpighia Punicifolia (Acerola) Fruit Extract, Adansonia Digitata Fruit Extract, Helianthus Annuus (Sunflower) Seed Oil, Simmondsia Chinensis (Jojoba) Seed Oil, Plumeria Acutifolia Flower Extract, Aloe Barbadensis Leaf Juice, Sodium Hyaluronate, Glycine Soja (Soybean) Oil, Tocopheryl Acetate, Tocopherol, Sorbitan Olivate, Polysorbate 60, Potassium Cetyl Phosphate, Acrylates/C10-30 Alkyl Acrylate Crosspolymer, Ethylhexylglycerin, Ethyl Hexanediol, Butylene Glycol, Caprylyl Glycol, Tromethamine, Phenoxyethanol, Parfum/Fragrance, Benzyl Salicylate, Hexyl Cinnamal, Limonene, Linalool.'] | M22: 32 | O22: 24 | P22: 1 | Q22: 0 | R22: 1 | S22: 0 | T22: 1 | U22: ['Vegan', 'Good for: Dullness/Uneven Texture', 'Hydrating', 'Clean at Sephora', 'Good for: Dryness'] | V22: Bath & Body | W22: Value & Gift Sets | Y22: 0 | AC22: 0.0025488118
A23: P502044 | B23: Mini Sparkling Cuvee Glass Jar Candle | C23: 6245 | D23: VOLUSPA | E23: 1158 | F23: 4.1667 | G23: 6 | H23: 5.5 oz / 156 g | I23: Size + Concentration + Formulation | J23: 5.5 oz / 156 g | M23: 20 | P23: 0 | Q23: 0 | R23: 0 | S23: 0 | T23: 0 | U23: ['Vegan', 'Without Phthalates', 'Without Parabens', 'Without Sulfates SLS & SLES', 'Cruelty-Free'] | V23: Fragrance | W23: Candles & Home Scents | X23: Candles | Y23: 0 | AC23: 0.0026192354
A24: P472340 | B24: Tea Tree Essential Oil | C24: 8020 | D24: SUNDAY II SUNDAY | E24: 2734 | F24: 4.25 | G24: 4 | H24: 1 oz/ 30 mL | I24: Size | J24: 1 oz/ 30 mL | L24: ['100% Pure Tea Tree Oil.'] | M24: 15 | P24: 0 | Q24: 0 | R24: 1 | S24: 0 | T24: 0 | U24: ['Vegan', 'All Hair Types', 'Good for: Frizz', 'Good for: Dryness', 'Without Parabens'] | V24: Hair | W24: Hair Styling & Treatments | X24: Hair Oil | Y24: 0 | AC24: 0.0026539865
A25: P434452 | B25: VIP Strong Hold Texturizing Hair Spray | C25: 6259 | D25: KÃ©rastase | E25: 5128 | F25: 3.8519 | G25: 27 | H25: 6.8 oz/ 193 g | I25: Size | J25: 6.8 oz/ 193 g | L25: ['Hydrofluorocarbon 152a, Alcohol Denat, Butane, Calcium Carbonate, Polyvinylcaprolactam, Disteardimonium Hectorite, Dimethicone, Fragrance, Dimethiconol, Benzyl Salicylate, Limonene, Benzyl Alcohol, Linalool, Citronellol, Geraniol, Hexyl Cinnamal, Hydroxycitronellal, Alpha-Isomethyl Ionone.'] | M25: 32 | P25: 0 | Q25: 0 | R25: 0 | S25: 1 | T25: 1 | U25: ['Good for: Volume', 'All Hair Types', 'Good for: Frizz'] | V25: Hair | W25: Hair Styling & Treatments | X25: Hair Spray | Y25: 0 | AC25: 0.0027013753
A26: P468829 | B26: Blond Absolu Strengthening Hair Oil for Very Damaged Blonde Hair | C26: 6259 | D26: KÃ©rastase | E26: 14239 | F26: 4.6159 | G26: 328 | H26: 3.4 oz/ 100 mL | I26: Size | J26: 3.4 oz/ 100 mL | L26: ['Cyclopentasiloxane, Dimethiconol, Parfum / Fragrance, Limonene, Helianthus Annuus Seed Oil / Sunflower Seed Oil, Linalool, Citronellol, Tocopherol, Leontopodium Alpinum Flower/Leaf Extract.'] | M26: 54 | P26: 0 | Q26: 0 | R26: 0 | S26: 0 | T26: 1 | U26: ['Good for: Damage', 'Floral Scent', 'All Hair Types', 'Good for: Dryness', 'Prevents Color Fading', 'Increases Shine'] | V26: Hair | W26: Hair Styling & Treatments | X26: Hair Oil | Y26: 1 | Z26: 26 | AA26: 26 | AC26: 0.0027729674
A27: P504785 | B27: Luxe Body Serum | C27: 5626 | D27: St. Tropez | E27: 1791 | F27: 4.8173 | G27: 892 | H27: 6.7 oz / 200 mL | I27: Size | J27: 6.7 oz / 200 mL | L27: ['Aqua (Water), Dihydroxyacetone, Butylene Glycol, Polysorbate 20, Trehalose, Phenoxyethanol, Hydroxyethylcellulose, Saccharide Isomerate, Panthenol, Sodium Metabisulfite, Parfum (Fragrance), Maltodextrin, Caramel, Citric Acid, Ethylhexylglycerin, Sodium Hyaluronate, Biosaccharide Gum-1, Linalool, Benzyl Salicylate, Niacinamide, Sodium Citrate, Coumarin, Limonene, Hexyl Cinnamal, Hydroxycitronellal, Geraniol, Alpha-Isomethyl Ionone, Sodium Hydroxide.'] | M27: 48 | P27: 0 | Q27: 1 | R27: 0 | S27: 0 | T27: 0 | U27: ['Vegan', 'Collagen', 'Hydrating', 'Niacinamide'] | V27: Bath & Body | W27: Body Moisturizers | X27: Body Lotions & Body Oils | Y27: 0 | AC27: 0.0027777238
A28: P479852 | B28: Melrose Place Moisturizing Body Cream | C28: 6144 | D28: OUAI | E28: 22152 | F28: 4.7096 | G28: 365 | H28: 7.5 oz/ 212 g | I28: Size | J28: 7.5 oz/ 212 g | L28: ['Aqua (Water, Eau), Caprylic/Capric Triglyceride, Phenyl Trimethicone, Cetyl Alcohol, Isododecane, Methyl Glucose Sesquistearate, Glycerin, Hydroxyethyl Acrylate/ Sodium Acryloyldimethyl Taurate Copolymer, Cocos Nucifera (Coconut) Oil, Sodium Stearoyl Glutamate, Glyceryl Stearate Citrate, Cetearyl Alcohol, Butyrospermum Parkii (Shea) Butter, Theobroma Grandiflorum Seed Butter, Lactobacillus Ferment, Squalane, Xanthan Gum, Citric Acid, Polysorbate 60, Ethylhexylglycerin, Glyceryl Caprylate, Tocopherol, Sodium Phytate, Sorbitan Isostearate, Benzophenone-4, Sodium Chloride, Alcohol, Phenoxyethanol, Parfum (Fragrance), Citronellol, Geraniol, Benzyl Salicylate, Linalool, Ci 14700 (Red 4), Ci 15985 (Yellow 6).'] | M28: 38 | P28: 0 | Q28: 0 | R28: 0 | S28: 0 | T28: 0 | U28: ['Cruelty-Free', 'Floral Scent', 'Hydrating', 'Good for: Dryness', 'Without Sulfates SLS & SLES'] | V28: Bath & Body | W28: Body Moisturizers | X28: Body Lotions & Body Oils | Y28: 0 | AC28: 0.00301315
A29: P503100 | B29: Soleil Neige Eye Color Quad | C29: 5869 | D29: TOM FORD | E29: 4436 | F29: 2.5 | G29: 4 | H29: 0.35 oz / 9.9 g | I29: Color | J29: Chalet Lust - rose golds and copper tones | L29: ['Mica, Cetearyl Ethylhexanoate, C12-20 Acid Peg-8 Ester, Hdi/Trimethylol Hexyllactone Crosspolymer, Squalane, Glycerin, Chondrus Crispus (Carrageenan), Ethylhexylglycerin, Dicalcium Phosphate, Silica, Aluminum Calcium Sodium Silicate, Synthetic Fluorphlogopite, Polysorbate 80, Tin Oxide, Caprylyl Glycol, 1,2-Hexanediol, [+/- Titanium Dioxide (Ci 77891), Iron Oxides (Ci 77491), Iron Oxides (Ci 77492), Iron Oxides (Ci 77499), Aluminum Powder (Ci 77000), Bismuth Oxychloride (Ci 77163), Blue 1 Lake (Ci 42090), Bronze Powder (Ci 77400), Carmine (Ci 75470), Chromium Hydroxide Green (Ci 77289), Chromium Oxide Greens (Ci 77288), Copper Powder (Ci 77400), Ferric Ammonium Ferrocyanide (Ci 77510), Ferric Ferrocyanide (Ci 77510), Manganese Violet (Ci 77742), Ultramarines (Ci 77007), Yellow 5 Lake (Ci 19140)].'] | M29: 90 | P29: 0 | Q29: 0 | R29: 0 | S29: 0 | T29: 0 | U29: ['Pressed Powder Formula', 'Shimmer Finish', 'Without Mineral Oil', 'Without Phthalates', 'Without Parabens', 'Without Triclosan'] | V29: Makeup | W29: Eye | X29: Eye Palettes | Y29: 1 | Z29: 90 | AA29: 90 | AC29: 0.0031015259
A30: P479342 | B30: Soft Pinch Blush Brush | C30: 6317 | D30: Rare Beauty by Selena Gomez | E30: 69220 | F30: 4.7143 | G30: 49 | M30: 23 | P30: 0 | Q30: 0 | R30: 0 | S30: 0 | T30: 1 | U30: ['Vegan', 'Cruelty-Free'] | V30: Makeup | W30: Brushes & Applicators | X30: Face Brushes | Y30: 0 | AC30: 0.0033103069
A31: P434500 | B31: Good Girl Rollerball | C31: 3155 | D31: Carolina Herrera | E31: 34288 | F31: 4.4665 | G31: 671 | H31: 0.30 oz/ 10 mL | I31: Size + Concentration + Formulation | J31: 0.30 oz/ 10 mL eau de parfum spray | L31: ['Alcohol Denat., Fragrance, Water, Linalool, Hydroxycitronellal, Benzyl Salicylate, Coumarin, Ethylhexyl Methoxycinnamate, Benzyl Benzoate, Ethylhexyl Saliclate, Butyl Methoxydibenzoylmethane, Limonen, Geraniol, Citronellol, Isoeugenol, Hexyl Cinnamal, Benzyl Alcohol, Citral, Ci 60730 (Ext. Violet 2) Alcohol Of Vegatal Origin 80%.'] | M31: 32 | P31: 0 | Q31: 0 | R31: 0 | S31: 0 | T31: 0 | V31: Fragrance | W31: Women | X31: Rollerballs & Travel Size | Y31: 0 | AC31: 0.003374984
A32: P428708 | B32: Patchouli Citrus Eau de Parfum | C32: 6238 | D32: The 7 Virtues | E32: 3882 | F32: 4.3093 | G32: 97 | H32: 1.7 oz/ 50 mL | I32: Size + Concentration + Formulation | J32: 1.7 oz/ 50 mL | L32: ['Organic Sugar Cane Alcohol Denat., Pogostemon Cablin, Water, Benzyl Alcohol, Benzyl Benzoate, Citral, Citronellol, Coumarin, Eugenol, Farnesol, Geraniol, Hydroxycitronellal, Limonene, Linalool, Lonones.'] | M32: 88 | P32: 0 | Q32: 0 | R32: 0 | S32: 0 | T32: 1 | U32: ['Vegan', 'Unisex/ Genderless Scent', 'Clean + Planet Positive', 'Without Phthalates', 'Hypoallergenic', 'Cruelty-Free'] | V32: Fragrance | W32: Women | X32: Perfume | Y32: 1 | Z32: 32 | AA32: 32 | AC32: 0.0033936965
A33: P500620 | B33: Mini Clay Play To-Go Cheek Palette | C33: 5648 | D33: tarte | E33: 25644 | F33: 4.303 | G33: 33 | L33: ['morning light:', 'Mica, Octyldodecyl Stearoyl Stearate, Synthetic Fluorphlogopite, Bis-Diglyceryl Polyacyladipate-2, Dimethicone, Pentaerythrityl Tetraisostearate, Phenoxyethanol, Silica, Ethylhexylglycerin, Tin Oxide, Kaolin, Tocopherol, Titanium Dioxide (CI 77891), Iron Oxides (CI 77491, CI 77492, CI 77499).', 'elements:', 'Mica, Octyldodecyl Stearoyl Stearate, Bis-Diglyceryl Polyacyladipate-2, Dimethicone, Pentaerythrityl Tetraisostearate, Phenoxyethanol, Silica, Ethylhexylglycerin, Tin Oxide, Kaolin, Tocopherol. (+/-): Titanium Dioxide (CI 77891), Iron Oxides (CI 77491, CI 77492, CI 77499), Red 7 Lake (CI 15850).', 'matte bronzer:', 'Mica, Dimethicone, Dimethicone/Vinyl Dimethicone Crosspolymer, Silica, Bis-Diglyceryl Polyacyladipate-2, Octyldodecyl Stearoyl Stearate, Pentaerythrityl Tetraisostearate, Phenoxyethanol, Ethylhexylglycerin, Kaolin, Tocopherol, Iron Oxides (CI 77491, CI 77492, CI 77499), Red 40 Lake (CI 16035), Titanium Dioxide (CI 77891).'] | M33: 25 | P33: 1 | Q33: 0 | R33: 0 | S33: 0 | T33: 0 | V33: Makeup | W33: Cheek | X33: Cheek Palettes | Y33: 0 | AC33: 0.0035148719
A34: P427314 | B34: Curl Control Mousse | C34: 6182 | D34: Moroccanoil | E34: 7535 | F34: 3.4146 | G34: 41 | H34: 5.1 oz/ 150 mL | I34: Size | J34: 5.1 oz/ 150 mL | L34: ['Water, Cocamidopropyl Hydroxysultaine, Polysorbate 20, Peg-40 Hydrogenated Castor Oil, Polyquaternium-72, Parfum/Fragrance, Argania Spinosa (Argan) Kernel Oil, Hydrolyzed Vegetable Protein PG-Propyl Silanetriol, Polyquaternium-11, Dipropylene Glycol, Phenoxyethanol, Tetrasodium EDTA, Citric Acid, Chlorphenesin, Polyquaternium-70, Caprylyl Glycol.'] | M34: 30 | P34: 0 | Q34: 0 | R34: 1 | S34: 0 | T34: 0 | V34: Hair | W34: Hair Styling & Treatments | X34: Hair Styling Products | Y34: 0 | AC34: 0.0036339355
A35: P471553 | B35: Legendary Conditioner | C35: 6162 | D35: IGK | E35: 1374 | F35: 4.3511 | G35: 262 | H35: 8 oz/ 236 mL | I35: Size | J35: 8 oz/ 236 mL | L35: ['Water (Aqua/Eau), Cetearyl Alcohol, Glycerin, Cetyl Esters, Butyrospermum Parkii (Shea) Butter, Behentrimonium Chloride, Fragrance (Parfum), Chondrus Crispus Extract, Eriophorum Spissum Flower/Stem Extract, Panthenol, Phenoxyethanol, Tilia Tomentosa Extract, Dimethicone, Dimethiconol, BHT, Disodium EDTA, Ethylhexylglycerin, Butyl Methoxydibenzoylmethane, Ethylhexyl Methoxycinnamate, Ethylhexyl Salicylate, Hydroxypropyltrimonium Hydrolyzed Corn Starch, Citric Acid, Sodium Hydroxide, Potassium Sorbate, Tocopherol, Sodium Benzoate, Sorbic Acid, Limonene.'] | M35: 32 | P35: 0 | Q35: 0 | R35: 0 | S35: 0 | T35: 0 | U35: ['Vegan', 'All Hair Types', 'Good for: Dryness', 'Without Parabens', 'Increases Shine'] | V35: Hair | W35: Shampoo & Conditioner | X35: Conditioner | Y35: 0 | AC35: 0.0036702977
A36: P385350 | B36: â€™REPLICAâ€™ Jazz Club | C36: 7038 | D36: Maison Margiela | E36: 62769 | F36: 4.5857 | G36: 980 | H36: 3.4 oz/ 100 mL | I36: Size + Concentration + Formulation | J36: 3.4 oz/ 100 mL | L36: ['Alcohol, Water, Fragrance, Ethylhexyl Methoxycinnamate, Coumarin, Limonene, Ethylhexyl Salicylate, Butyl Methoxydibenzoylmethane, Linalool, Citral, Geraniol, Ci 15985/Yellow 6, Cinnamal, Hydroxycitronellal, Eugenol Citronellol, Ci 19140/Yellow 5, Ci 17200/Red 33, Ci 42090/Blue 1, C162585/2.'] | M36: 160 | P36: 0 | Q36: 0 | R36: 0 | S36: 0 | T36: 0 | U36: ['Unisex/ Genderless Scent', 'Warm &Spicy Scent'] | V36: Fragrance | W36: Women | X36: Perfume | Y36: 2 | Z36: 85 | AA36: 35 | AC36: 0.0036823835
A37: P483696 | B37: Gentle Micellar Antioxidant Cleanser | C37: 6488 | D37: The Outset | E37: 3860 | F37: 4.6937 | G37: 111 | H37: 5 oz / 150 mL | I37: Size | J37: 5 oz / 150 mL | L37: ['Water (Aqua, Eau), Propanediol, Glycerin, Triheptanoin, Coco-Caprylate/Caprate, Sodium Polyacryloyldimethyl Taurate, Capryloyl Glycerin/Sebacic Acid Copolymer, Cassia Angustifolia Seed Polysaccharide, Helianthus Annuus (Sunflower) Seed Oil, Heterotheca Inuloides Flower Extract, Chenopodium Quinoa Seed Extract, Poncirus Trifoliata Fruit Extract, Hydrolyzed Brassica Napus Seedcake Extract, SR-Hydrozoan Polypeptide-1, Castor Oil/IPDI Copolymer, Diheptyl Succinate, Phenoxyethanol, Dilinoleic Acid/Butanediol Copolymer, Caprylyl Glycol, Hydrolyzed Jojoba Esters, Lysolecithin, Sclerotium Gum, Tetrahexyldecyl Ascorbate, Tocopheryl Acetate, Tetrasodium Glutamate Diacetate, Pullulan, Xanthan Gum, Jojoba Esters, Silica, Citric Acid, Sodium Benzoate, Sodium Formate, Sodium Glycolate, Sodium Hydroxide, Sodium PCA, Potassium Hydroxide, Potassium Sorbate.'] | M37: 32 | P37: 0 | Q37: 0 | R37: 0 | S37: 0 | T37: 1 | U37: ['Vegan', 'Clean + Planet Positive', 'Hydrating', 'Fragrance Free', 'Hypoallergenic', 'Cruelty-Free'] | V37: Skincare | W37: Cleansers | X37: Face Wash & Cleansers | Y37: 0 | AC37: 0.0036955222
A38: P504312 | B38: Donna Born In Roma Intense Eau de Parfum | C38: 1169 | D38: Valentino | E38: 13815 | F38: 4.6988 | G38: 581 | H38: 0.34 oz / 10 mL | I38: Size + Concentration + Formulation | J38: 0.34 oz / 10 mL eau de parfum spray | L38: ['Alcohol, Parfum/Fragrance, Aqua/Water/Eau, Benzyl Salicylate, Benzyl Alcohol, Ethylhexyl Salicylate, Butyl Methoxydibenzoylmethane, Hydroxycitronellal, Coumarin, Limonene, Linalool, Alpha-Isomethyl Ionone, Anise Alcohol, Isoeugenol, Methyl Anthranilate, Benzyl Benzoate, Citronellol, Geraniol, Benzyl Cinnamate, Tris (Tetramethylhydroxypiperidinol) Citrate, Citral, Cinnamal, Eugenol, Farnesol, CI 14700/Red 4, CI 17200/Red 33, CI 60730/Ext. Violet 2.'] | M38: 35 | P38: 0 | Q38: 1 | R38: 0 | S38: 0 | T38: 0 | U38: ['Layerable Scent', 'Floral Scent'] | V38: Fragrance | W38: Women | X38: Perfume | Y38: 3 | Z38: 156 | AA38: 85 | AC38: 0.0037187748
A39: P501243 | B39: GOOPGLOW Exfoliating Dark Spot Sleep Serum | C39: 6309 | D39: goop | E39: 2143 | F39: 4.0598 | G39: 251 | H39: 1 oz / 30 mL | I39: Size | J39: 1 oz / 30 mL | L39: ['Aqua/Water/Eau, Caprylic/Capric Triglyceride, Glycolic Acid, Squalane, Sodium Hydroxide, Behenyl Alcohol, Gluconolactone, Lactic Acid, Glycerin, Polyglyceryl-10 Dioleate, Pentylene Glycol, Propanediol, Magnesium Aluminum Silicate, Sodium Hyaluronate, Aloe Barbadensis Leaf Juice, Salicornia Herbacea Extract, Hydrogenated Lecithin, Hibiscus Sabdariffa Flower Extract, Piperonyl Glucoside, Polyglutamic Acid, Avena Sativa (Oat) Bran Extract, Tamarindus Indica Seed Polysaccharide, Simmondsia Chinensis (Jojoba) Seed Oil, Adansonia Digitata Seed Oil, Citrullus Lanatus (Watermelon) Seed Oil, Phospholipids, Adansonia Digitata Fruit Extract, Cyclodextrin, Xanthan Gum, Glyceryl Undecylenate, Glyceryl Caprylate, Tetrasodium Glutamate Diacetate, Caprylyl Glycol, Ethylhexylglycerin, Sclerotium Gum, 1,2-Hexanediol, Polyglyceryl-10 Dipalmitate, Sodium Benzoate, Potassium Sorbate, Citric Acid.'] | M39: 98 | P39: 0 | Q39: 0 | R39: 0 | S39: 0 | T39: 0 | U39: ['Good for: Dullness/Uneven Texture', 'Hyaluronic Acid', 'Clean at Sephora', 'AHA/Glycolic Acid', 'Best for Dry, Combo, Normal Skin', 'Good for: Dark spots'] | V39: Skincare | W39: Treatments | X39: Face Serums | Y39: 0 | AC39: 0.003890582
A40: P426000 | B40: Mini Texturizing Hair Spray | C40: 6144 | D40: OUAI | E40: 14727 | F40: 3.2632 | G40: 95 | H40: 1.4 oz | I40: Size | J40: 1.4 oz | L40: ['Hydrofluorocarbon 152A, Dimethyl Ether, Alcohol Denat., VP/VA Copolymer, Panthenol, Tocopheryl Acetate, Actinidia Chinensis (Kiwi) Fruit Extract, Aloe Barbadensis (Aloe Vera) Leaf Extract, Hedychium Coronarium (Ginger) Root Extract, Mangifera Indica (Mango) Fruit Extract, Passiflora Incarnata (Passion Flower) Extract, Helianthus Annuus (Sunflower) Seed Extract, Glycerin, Acetyl Triethyl Citrate, Fragrance, Zeolite, Butylene Glycol, Water, PEG/PPG-17/18 Dimethicone, Benzoic Acid, Sorbic Acid, Phenoxyethanol, Chlorphenesin, Benzyl Salicylate, Hexyl Cinnamal, Limonene, Butylphenyl Methylpropional, Linalool, Hydroxycitronellal.'] | M40: 14 | P40: 1 | Q40: 0 | R40: 0 | S40: 0 | T40: 0 | V40: Mini Size | W40: Hair | Y40: 0 | AC40: 0.0040554452
...

Sheet Beauty_500_Raw
A1: product_id | B1: product_name | C1: brand_id | D1: brand_name | E1: loves_count | F1: rating | G1: reviews | H1: size | I1: variation_type | J1: variation_value | K1: variation_desc | L1: ingredients | M1: price_usd | N1: value_price_usd | O1: sale_price_usd | P1: limited_edition | Q1: new | R1: online_only | S1: out_of_stock | T1: sephora_exclusive | U1: highlights | V1: primary_category | W1: secondary_category | X1: tertiary_category | Y1: child_count | Z1: child_max_price | AA1: child_min_price | AC1: Rating_category
A2: P453279 | B2: Mini Intenso Smoothing Mask for Thick Hair | C2: 6159 | D2: Rossano Ferretti Parma | E2: 557 | F2: 3 | G2: 2 | H2: 1.7 oz/ 50 mL | I2: Size | J2: 1.7 oz/ 50 mL | M2: 18 | P2: 0 | Q2: 0 | R2: 1 | S2: 0 | T2: 0 | U2: ['Vegan', 'Hydrating', 'Clean at Sephora', 'Good for: Frizz', 'Good for: Dryness', 'Cruelty-Free'] | V2: Hair | W2: Hair Styling & Treatments | X2: Hair Masks | Y2: 0 | AC2: =IF(F2="","Not Rated", IF(F2>4,"High Rated","Low Rated")) -> Low Rated
A3: P501449 | B3: PEPTIDE PREP Clarifying Detox Shampoo | C3: 6472 | D3: K18 Biomimetic Hairscience | E3: 24418 | F3: 4.7944 | G3: 603 | H3: 8.5 oz / 250 mL | I3: Size | J3: 8.5 oz / 250 mL | L3: ['Water (Aqua) (Eau), Sodium C14-16 Olefin Sulfonate, Cocamidopropyl Hydroxysultaine, Salicylic Acid, Charcoal Powder, sh-Oligopeptide-78, Panthenol,', 'Glycerin, Sodium Phytate, Guar Hydroxypropyltrimonium Chloride, Caprylyl Glycol, Caprylhydroxamic Acid, Citric Acid, Potassium Hydroxide, Sodium Hydroxide, Fragrance (Parfum), Benzyl Salicylate, Limonene.'] | M3: 38 | P3: 0 | Q3: 0 | R3: 0 | S3: 0 | T3: 1 | U3: ['Vegan', 'Good for: Color Care', 'Clean at Sephora', 'All Hair Types', 'Salicylic Acid', 'Good for: Oily Scalp'] | V3: Hair | W3: Shampoo & Conditioner | X3: Shampoo | Y3: 1 | Z3: 14 | AA3: 14 | AC3: =IF(F3="","Not Rated", IF(F3>4,"High Rated","Low Rated")) -> High Rated
A4: P501526 | B4: Even Better All-Over Primer + Color Corrector | C4: 1254 | D4: CLINIQUE | E4: 2159 | F4: 3.8 | G4: 5 | H4: 0.2 oz / 6 mL | I4: Color | J4: Peach | K4: very fair to moderately fair complexions | L4: ['Water/Aqua/Eau, Methyl Trimethicone, Trimethylsiloxysilicate, Dimethicone, Butylene Glycol, Phenyl Trimethicone, Neopentyl Glycol Diheptanoate, Niacinamide, Hydroxyethyl Urea, Lauryl PEG-9 Polydimethylsiloxyethyl Dimethicone, Glycerin, Sodium Polyaspartate, Ascorbyl Glucoside, Phytosphingosine, Palmitoyl Hexapeptide-12, Sodium Hyaluronate, Resveratrol, Acetyl Hexapeptide-8, Caffeine, Magnesium Ascorbyl Phosphate, Tetrahexyldecyl Ascorbate, Polygonum Cuspidatum Root Extract, Tocopheryl Acetate, PEG-10 Dimethicone, Triethyl Citrate, Sigesbeckia Orientalis (St. Paul Wort) Extract, Micrococcus Lysate, Isopropyl Isostearate, PPG-15 Stearyl Ether, Salicylic Acid, Trihydroxystearin, Caprylyl Glycol, Sorbitol, Trehalose, Silica, Dimethicone/PEG-10/15 Crosspolymer, Xanthan Gum, Magnesium Aluminum Silicate, Lecithin, Triethoxycaprylylsilane, Zinc Stearate, Laureth-7, PEG-8, Ammonium Acryloyldimethyltaurate/VP Copolymer, Glyceryl Polymethacrylate, Alumina, Propylene Glycol Caprylate, Polysilicone-11, Disteardimonium Hectorite, Citric Acid, Hexylene Glycol, Dipropylene Glycol, Vinyl Dimethicone/Methicone Silsesquioxane Crosspolymer, Sodium Chloride, Sodium Hydroxide, BHT, Disodium EDTA, Sodium Citrate, Potassium Sorbate, Phenoxyethanol, [+/- Mica, Titanium Dioxide (CI 77891), Iron Oxides (CI 77491), Iron Oxides (CI 77492), Iron Oxides (CI 77499), Bismuth Oxychloride (CI 77163), Ultramarines (CI 77007), Chromium Oxide Greens (CI 77288)].'] | M4: 29 | P4: 0 | Q4: 0 | R4: 1 | S4: 0 | T4: 0 | U4: ['Natural Finish', 'Hyaluronic Acid', 'Vitamin C', 'Good for: Dark Circles', 'Long-wearing', 'Niacinamide'] | V4: Makeup | W4: Face | X4: Face Primer | Y4: 1 | Z4: 29 | AA4: 29 | AC4: =IF(F4="","Not Rated", IF(F4>4,"High Rated","Low Rated")) -> Low Rated
A5: P422093 | B5: Bloom Eau de Parfum For Her | C5: 1063 | D5: Gucci | E5: 69220 | F5: 4.1913 | G5: 1317 | H5: 1.6 oz/ 50 mL | I5: Size + Concentration + Formulation | J5: 1.6 oz/ 50 mL Eau de Parfum Spray | L5: ['Alcohol Denat., Fragrance, Water, Ethylhexyl Methoxycinnamate, Diethylamino Hydroxybenzoyl Hexyl Benzoate, Bht, Linalool, Benzyl Alcohol, Cinnamal, Hydroxycitronellal, Citronellol, Geraniol, Eugenol, Isoeugenol, Farnesol, Benzyl Benzoate, Hexyl Cinnamal, Citral.'] | M5: 123 | P5: 0 | Q5: 0 | R5: 0 | S5: 0 | T5: 0 | U5: ['Floral Scent', 'Layerable Scent'] | V5: Fragrance | W5: Women | X5: Perfume | Y5: 3 | Z5: 155 | AA5: 38 | AC5: =IF(F5="","Not Rated", IF(F5>4,"High Rated","Low Rated")) -> High Rated
A6: P9549 | B6: ALLURE Eau de Parfum | C6: 1065 | D6: CHANEL | E6: 7564 | F6: 4.3077 | G6: 26 | H6: 1.7 oz | I6: Size | J6: 1.7 oz | L6: ['Alcohol, Fragrance, Water, Linalool, Benzyl Salicylate, Limonene, Hexyl Cinnamal, Hydroxycitronellal, Citronellol, Geraniol, Alpha-Isomethyl Ionone, Coumarin, Citral, Benzyl Benzoate, Farnesol, Benzyl Alcohol, Amyl Cinnamal, Isoeugenol, Eugenol, Ethylhexyl Methoxycinnamate, Butyl Methoxydibenzoylmethane, Ethylhexyl Salicylate, Ci 14700 (Red 4), Ci 42090 (Blue 1), Ci 15985 (Yellow 6), Ci 19140 (Yellow 5), Il18-1.'] | M6: 122 | P6: 0 | Q6: 0 | R6: 0 | S6: 0 | T6: 0 | V6: Fragrance | W6: Women | X6: Perfume | Y6: 0 | AC6: =IF(F6="","Not Rated", IF(F6>4,"High Rated","Low Rated")) -> High Rated
A7: P408230 | B7: V-Facial Instant Depuffing Face Mask | C7: 2082 | D7: Clarins | E7: 26393 | F7: 4.7547 | G7: 159 | H7: 2.5 oz/ 74 mL | I7: Size | J7: 2.5 oz/ 74 mL | L7: ['Water, Glycerin, Kaolin, Alcohol, Cetearyl Ethylhexanoate, Cetearyl Alcohol, Betaine, Cetyl Alcohol, Polymethyl Methacrylate, Butylene Glycol, Caffeine, Glyceryl Stearate, Ci 77891/Titanium Dioxide, Gellan Gum, Dimethicone, Phenoxyisopropanol, Escin, Ethylhexylglycerin, Sodium Cetearyl Sulfate, Sodium Lauryl Sulfate, Sodium Acrylates Copolymer, Hydrogenated Polyisobutene, Disodium Edta, Zingiber Zerumbet Extract, Parfum/Fragrance, Phospholipids, Polyglyceryl-10 Stearate, Helianthus Annuus (Sunflower) Seed Oil, Tromethamine, Alumina, Ethylene Brassylate, Xylitol, Alchemilla Vulgaris Extract, Callicarpa Japonica Fruit Extract.'] | M7: 67 | P7: 0 | Q7: 0 | R7: 0 | S7: 0 | T7: 0 | U7: ['Good for: Dullness/Uneven Texture', 'Good for: Loss of firmness', 'Without Phthalates', 'Without Parabens', 'Best for Dry, Combo, Normal Skin'] | V7: Skincare | W7: Masks | X7: Face Masks | Y7: 0 | AC7: =IF(F7="","Not Rated", IF(F7>4,"High Rated","Low Rated")) -> High Rated
A8: P500716 | B8: 10 Day Results Kit | C8: 6018 | D8: Algenist | E8: 3206 | F8: 4.8023 | G8: 258 | L8: ['GENIUS Liquid Collagen:', 'Collagen (Vegan), Water (Aqua, Eau), Propanediol, Isononyl Isononanoate, Butylene Glycol, Glycerin, Betaine, Pentylene Glycol, Dextrin Palmitate, Collagen Amino Acids (Vegan), Parachlorella Beijerinckii Exopolysaccharides, Chlorella Protothecoides Oil, Helichrysum Stoechas Flower Extract, Cylindrotheca Fusiformis Extract, Niacinamide, Tocopherol, Palmitoyl Tripeptide-1, Palmitoyl Tetrapeptide-7, Adenosine, Helianthus Annuus (Sunflower) Seed Oil, Leuconostoc/Radish Root Ferment Filtrate, Caprylic/Capric Triglyceride, Palmitic Acid, Disodium EDTA, Carbomer, Sodium Lactate, Amodimethicone, Homosalate, Polysorbate 20, Butyl Methoxydibenzoylmethane, 1,2-Hexanediol, Caprylyl Glycol, Octocrylene, Sodium Hydroxide, Phenoxyethanol, Fragrance (Parfum), Limonene, Beta-Carotene (CI 40800).', 'Triple Algae Eye Renewal Balm with Multi-Peptide Complex:', 'Aqua (Water/Eau), Stearic Acid, Isopropyl Isostearate, Dimethicone, Glycerin, Pentylene', 'Glycol, Glyceryl Stearate SE, Cetearyl Alcohol, Butyrospermum Parkii (Shea) Butter, C12-15 Alkyl Benzoate, Limnanthes Alba (Meadowfoam) Seed Oil, Parachlorella Beijerinckii Exopolysaccharides, Corallina Officinalis Extract, Dunaliella Salina Extract, Undaria Pinnatifida Extract, Dipeptide-2, Palmitoyl Tetrapeptide-7, Palmitoyl Hexapeptide-12, Palmitoyl Tripeptide-5, Sodium Hyaluronate, Caffeine, Coffea Arabica (Coffee) Seed Oil, Tribehenin, Ceramide NG, PEG-10 Phytosterol, Tetrahexyldecyl Ascorbate, Aloe Barbadensis Leaf Juice, Tocopheryl Acetate, Bambusa Vulgaris Leaf/Stem Extract, Pisum Sativum (Pea)', 'Extract, Glucosamine HCl, Leuconostoc/Radish Root Ferment Filtrate, Camellia Sinensis Leaf Extract, Cucumis Sativus (Cucumber) Fruit Extract, Dimethicone Crosspolymer, Panthenol, Pantolactone, Caprylyl/Capryl Glucoside, Pfaffia Paniculata Root Extract, Ptychopetalum Olacoides Bark/Stem Extract, Lilium Candidum Flower Extract, Rubus Idaeus (Raspberry) Leaf Extract, Aloe Barbadensis Leaf Juice Powder, Vinyl Dimethicone/Methicone Silsesquioxane Crosspolymer, Phospholipids, Ceteareth-20, Acrylates/C10-30 Alkyl Acrylate Crosspolymer, Disodium EDTA, Aminomethyl Propanol, Caprylyl Glycol, Lactic Acid, Ethylhexylglycerin, Hexylene Glycol, Hesperidin Methyl Chalcone, Steareth-20, Citric Acid, Sodium Citrate, Chlorhexidine Digluconate, Phenoxyethanol, Potassium Sorbate, Benzyl Alcohol, Sodium Benzoate.', 'GENIUS Ultimate Anti-Aging Cream:', 'Water (Aqua, Eau), Caprylic/Capric Triglyceride, Hydrogenated Polyisobutene, Glycerin, Chlorella Protothecoides Oil, Dimethicone, Butylene Glycol, Glyceryl Stearate, PEG-100 Stearate, Butyrospermum Parkii (Shea) Butter, Pentylene Glycol, Potassium Cetyl Phosphate, Parachlorella Beijerinckii Exopolysaccharides, Collagen (Vegan), Ceramide NP, Cynara Scolymus (Artichoke) Leaf Extract, Retinyl Palmitate, Astragalus Membranaceus Root Extract, Atractylodes Macrocephala Root Extract, Iris Florentina Root Extract, Bupleurum Falcatum Root Extract, Copper Lysinate/Prolinate, Methylglucoside Phosphate, Stearalkonium Bentonite, Acrylates/C10-30 Alkyl Acrylate Crosspolymer, Silica, Caprylyl Glycol, Sodium Hydroxide, Disodium EDTA, Ethylhexylglycerin, Cetyl Alcohol, Propylene Carbonate, Quartz, Phenoxyethanol, Leuconostoc/Radish Root Ferment Filtrate, Chlorphenesin, Fragrance (Parfum), Coumarin.'] | M8: 88 | N8: 142 | P8: 0 | Q8: 0 | R8: 0 | S8: 0 | T8: 1 | U8: ['Vegan', 'Good for: Loss of firmness', 'Good for: Dark Circles', 'Collagen', 'Hydrating', 'Good for: Anti-Aging'] | V8: Skincare | W8: Value & Gift Sets | Y8: 0 | AC8: =IF(F8="","Not Rated", IF(F8>4,"High Rated","Low Rated")) -> High Rated
A9: P502274 | B9: Paper- Personal | C9: 7095 | D9: Commodity | E9: 664 | F9: 3.5455 | G9: 11 | H9: 3.4 oz / 100 mL | I9: Size + Concentration + Formulation | J9: 3.4 oz / 100 mL perfume spray | L9: ['SD Alcohol 40-B (Alcohol Denat.), Parfum/Fragrance, Aqua/Water/Eau.'] | M9: 135 | P9: 0 | Q9: 0 | R9: 0 | S9: 0 | T9: 1 | U9: ['Vegan', 'Unisex/ Genderless Scent', 'Clean at Sephora', 'Cruelty-Free'] | V9: Fragrance | W9: Women | X9: Perfume | Y9: 1 | Z9: 25 | AA9: 25 | AC9: =IF(F9="","Not Rated", IF(F9>4,"High Rated","Low Rated")) -> Low Rated
A10: P462706 | B10: Epic Curl Vegan Lash Primer | C10: 5905 | D10: KVD Beauty | E10: 2352 | F10: 2.9355 | G10: 31 | L10: ['Aqua/Water/Eau, Hydrogenated Olive Oil Stearyl Esters, Bambusa Arundinacea Stem Extract, Cera, Carnauba/Copernicia, Cerifera (Carnauba) Wax/Cire De Carnauba, Oryza Sativa Cera/Oryza Sativa (Rice) Bran Wax, Glyceryl Stearate, Helianthus Annuus Seed Cera/Helianthus Annuus (Sunflower) Seed Wax, Bis-Diglyceryl Polyacyladipate-2, Acacia Senegal Gum, Stearic Acid, Propanediol, Palmitic Acid, Aminomethyl Propanol, Hydrolyzed Jojoba Esters, Phenoxyethanol, Sodium Dehydroacetate, Galactoarabinan, Jojoba Esters, Xanthan Gum, Ethylhexylglycerin, Talc, Kaolin, Tocopherol, Ultramarines (Ci 77007), Iron Oxides (Ci 77499), Ferric Ammonium Ferrocianide (Ci 77510).'] | M10: 24 | P10: 0 | Q10: 0 | R10: 0 | S10: 0 | T10: 0 | U10: ['Vegan', 'Liquid Formula', 'Curling'] | V10: Makeup | W10: Eye | X10: Mascara | Y10: 0 | AC10: =IF(F10="","Not Rated", IF(F10>4,"High Rated","Low Rated")) -> Low Rated
A11: P376726 | B11: Maracuja Oil | C11: 5648 | D11: tarte | E11: 79986 | F11: 4.396 | G11: 2419 | H11: 1.7 oz/ 50 mL | I11: Size | J11: 1.7 oz/ 50 mL | L11: ['Passiflora Edulis Seed Oil, Citrus Paradisi (Grapefruit) Peel Oil, Limonene, Tocopherol, Oryza Sativa (Rice) Bran Extract, Helianthus Annuus (Sunflower) Extract, Rosmarinus Officinalis (Rosemary) Leaf Extract, Citral, Linalool.'] | M11: 48 | P11: 0 | Q11: 0 | R11: 0 | S11: 0 | T11: 0 | V11: Skincare | W11: Moisturizers | X11: Face Oils | Y11: 1 | Z11: 16 | AA11: 16 | AC11: =IF(F11="","Not Rated", IF(F11>4,"High Rated","Low Rated")) -> High Rated
A12: P504146 | B12: Sunday Scalp Reset Foam Pre Shampoo | C12: 5995 | D12: Bumble and bumble | E12: 292 | F12: 4.766 | G12: 47 | H12: 3.5 oz / 150 mL | I12: Size | J12: 3.5 oz / 150 mL | L12: ['Butane, Water/Aqua/Eau, Alcohol Denat., Isobutane, Glycerin, Butylene Glycol, Dimethicone, Fragrance (Parfum), Caprylic/Capric Triglyceride, PPG-8-Ceteth-20, Salicylic Acid, Caffeine, Epilobium Angustifolium Flower/Leaf/Stem Extract, Sodium Lauroamphoacetate, Panthenol, Tocopheryl Acetate, Punica Granatum (Pomegranate) Extract, Honey Extract/Mel/Extrait De Miel, Leuconostoc/Radish Root Ferment Filtrate, Wheat Amino Acids, Aloe Barbadensis Leaf Juice, Gellidiella Acerosa Extract, Hypnea Musciformis (Algae) Extract, Sargassum Filipendula (Algae) Extract, Citrus Tangerina (Tangerine), Zingiber Officinale (Ginger) Root Extract, Rice Amino Acids, Glyceryl Polyacrylate, Hydroxyethylcellulose, Biotin, Cellulose, Cocamide Mipa, Sodium Lauroyl Methyl Isethionate, Citric Acid, Linalool, Benzyl Salicylate, Citronellol, Limonene, Alpha-Isomethyl Ionone, Phenoxyethanol, Sodium Benzoate.'] | M12: 34 | P12: 0 | Q12: 0 | R12: 0 | S12: 0 | T12: 1 | U12: ['Good for: Color Care', 'Salicylic Acid', 'Without Sulfates SLS & SLES', 'Good for: Oily Scalp', 'Cruelty-Free'] | V12: Hair | W12: Hair Styling & Treatments | X12: Scalp Treatments | Y12: 0 | AC12: =IF(F12="","Not Rated", IF(F12>4,"High Rated","Low Rated")) -> High Rated
A13: P462356 | B13: Mini Honey Infused Hair Perfume | C13: 6328 | D13: Gisou | E13: 70086 | F13: 4.0824 | G13: 425 | H13: 1.7 oz/ 50 mL | I13: Size | J13: 1.7 oz/ 50 mL | L13: ['Alcohol Denat., Parfum (Fragrance), Aqua (Water, Eau), Mel (Honey, Miel)*, Argania Spinosa Kernel Oil, Sodium Benzotriazolyl Butylphenol Sulfonate, Tris(Tetramethylhydroxypiperidinol) Citrate, Citral**, Coumarin**, Linalool**, Hexyl Cinnamal**, Limonene**, CI 19140 (Yellow 5), CI 14700 (Red 4).'] | M13: 44 | P13: 0 | Q13: 0 | R13: 0 | S13: 0 | T13: 0 | U13: ['Layerable Scent', 'Fresh Scent', 'Clean at Sephora', 'All Hair Types', 'Good for: Frizz'] | V13: Hair | W13: Hair Styling & Treatments | X13: Hair Styling Products | Y13: 0 | AC13: =IF(F13="","Not Rated", IF(F13>4,"High Rated","Low Rated")) -> High Rated
A14: P462386 | B14: Drying Cream | C14: 8017 | D14: Mario Badescu | E14: 1635 | F14: 3.75 | G14: 4 | H14: 0.5 oz/ 14 g | I14: Size | J14: 0.5 oz/ 14 g | L14: ['Aqua (Water, Eau), Zinc Oxide, Cetyl Alcohol, Aloe Barbadensis Leaf Juice, Cera Alba (Beeswax, Cire dÂ´abeille), Polysorbate 80, Glycerin, Ethylhexyl Palmitate, Propylene Glycol, Sulfur, Oleth-10, Paraffinum Liquidum (Mineral Oil, Huile MinÃ©rale), Ichthammol, Hydrolyzed Yeast Protein, Triticum Vulgare (Wheat) Starch, Arctium Lappa Root Extract, Cysteine, Niacinamide, Panthenol, Nasturtium Officinale Flower/Leaf Extract, Citrus Limon (Lemon) Fruit Extract, Allantoin, Biotin, Arginine, Leucine, Lysine, Tyrosine, Valine, Glutamic Acid, Cellulose Gum, Polysorbate 20, Maltodextrin, Zinc Chloride, Glyceryl Acrylate/Acrylic Acid Copolymer, Pyridoxine HCl, Parfum (Fragrance), Sodium Chloride, Methylparaben, Propylparaben, Potassium Sorbate, Citric Acid, Sodium Benzoate, Chlorphenesin, Disodium EDTA, Phenoxyethanol, Benzyl Benzoate, Alpha-Isomethyl Ionone, Limonene, Linalool, CI 77891 (Titanium Dioxide).'] | M14: 17 | P14: 0 | Q14: 0 | R14: 1 | S14: 0 | T14: 0 | V14: Skincare | W14: Treatments | X14: Blemish & Acne Treatments | Y14: 0 | AC14: =IF(F14="","Not Rated", IF(F14>4,"High Rated","Low Rated")) -> Low Rated
A15: P437657 | B15: Scalp Care Dry Scalp Treatment | C15: 5936 | D15: Living Proof | E15: 33713 | F15: 4.301 | G15: 309 | H15: 3.4 oz/ 100 mL | I15: Size | J15: 3.4 oz/ 100 mL | L15: ['Water/Eau/Aqua, Glycerin, Niacinamide, Sodium Hyaluronate, Trehalose, Urea, Serine, Algin, Pentylene Glycol, Pullulan, Lecithin, Glyceryl Polyacrylate, C13-15 Alkane, Caprylyl Glycol, Disodium Phosphate, Potassium Phosphate, Hydroxyethyl Acrylate/Sodium Acryloyldimethyl Taurate Copolymer, Hydroxyacetophenone, Caesalpinia Spinosa Gum, Sclerotium Gum, Xanthan Gum, Isohexadecane, Ethylhexylglycerin, Polysorbate 60, Fragrance/Parfum.'] | M15: 37 | P15: 0 | Q15: 0 | R15: 0 | S15: 0 | T15: 0 | U15: ['Vegan', 'All Hair Types', 'Without Parabens', 'Without Silicones', 'Without Sulfates SLS & SLES', 'Good for: Flaky/Dry Scalp'] | V15: Hair | W15: Hair Styling & Treatments | X15: Scalp Treatments | Y15: 0 | AC15: =IF(F15="","Not Rated", IF(F15>4,"High Rated","Low Rated")) -> High Rated
